Workbook

Sheet README
B2: Student Performance Prediction System
B3: Predicting Pass/Fail risk from Attendance, Study Hours and Previous Marks — 1,000 students, 1 all-in-one Dashboard, 15 pivot tables.
B5: Problem It Solves
B6: Teachers often notice a student is struggling only after a test has already been failed. By the time report cards go out, there is no time left to intervene. This workbook flags at-risk students EARLY, using data that is already available: attendance, weekly study hours, and previous exam marks.
B7: With 1,000 students across 4 sections, no teacher can eyeball every record — this workbook turns raw rows into a ranked risk list, 15 pivot summaries, and dashboards so the people who most need help are surfaced automatically.
B9: How This System Solves It
B10: 1. Store each student's Attendance %, Study Hours/Week and Previous Marks % in the 'Student Data' sheet.
B11: 2. A formula converts those three inputs into a single Performance Score (0-100), a Predicted Result (PASS/FAIL) and a Risk Level (High/Medium/Low) — for every student, instantly, with zero manual work.
B12: 3. The 'Pivot Summary' sheet slices those results 15 different ways (by risk, result, score band, attendance band, study-hours band, previous-marks band, gender, section, four cross-tabs, and ranked Top 10 / Bottom 10 performer lists).
B13: 4. The single 'Dashboard' sheet turns those pivots into KPI cards, 11 chart/table sections and ranked lists a teacher or head of department can act on in under a minute, all on one scrollable page.
B15: How The Prediction Works (the formula)
B16: Performance Score = ROUND( 0.4 x Previous Marks% + 0.3 x Attendance% + 0.3 x MIN(Study Hours/10, 1) x 100 , 1 )
... B49: Add slicers to a native Excel PivotTable for point-and-click filtering by section, gender or risk level, alongside the fixed Dashboard sheet already built here.

Sheet Student Data
A1: Student Data (blue cells = editable inputs; other columns are formulas) — 1,000 students
A2: Student ID | B2: Name | C2: Gender | D2: Section | E2: Attendance (%) | F2: Study Hours/Week | G2: Previous Marks (%) | H2: Performance Score | I2: Predicted Result | J2: Risk Level | K2: Notes | L2: HighRiskRank | M2: PerfRank
A3: STU0001 | B3: Amit Desai | C3: Male | D3: A | E3: 92 | F3: 5 | G3: 56 | H3: =ROUND(0.4*G3+0.3*E3+0.3*MIN(F3/10,1)*100,1) -> 65 | I3: =IF(H3>=50,"PASS","FAIL") -> PASS | J3: =IF(H3<50,"High Risk",IF(H3<65,"Medium Risk","Low Risk")) -> Low Risk | L3: =IF(J3="High Risk",COUNTIF($J$3:J3,"High Risk"),"") | M3: =RANK(H3,$H$3:$H$1002,0)+COUNTIF($H$3:H3,H3)-1 -> 531
A4: STU0002 | B4: Ravi Singh | C4: Male | D4: A | E4: 87.3 | F4: 5.7 | G4: 69 | H4: =ROUND(0.4*G4+0.3*E4+0.3*MIN(F4/10,1)*100,1) -> 70.9 | I4: =IF(H4>=50,"PASS","FAIL") -> PASS | J4: =IF(H4<50,"High Risk",IF(H4<65,"Medium Risk","Low Risk")) -> Low Risk | L4: =IF(J4="High Risk",COUNTIF($J$3:J4,"High Risk"),"") | M4: =RANK(H4,$H$3:$H$1002,0)+COUNTIF($H$3:H4,H4)-1 -> 412
A5: STU0003 | B5: Divya Yadav | C5: Female | D5: C | E5: 74.8 | F5: 7.1 | G5: 55 | H5: =ROUND(0.4*G5+0.3*E5+0.3*MIN(F5/10,1)*100,1) -> 65.7 | I5: =IF(H5>=50,"PASS","FAIL") -> PASS | J5: =IF(H5<50,"High Risk",IF(H5<65,"Medium Risk","Low Risk")) -> Low Risk | L5: =IF(J5="High Risk",COUNTIF($J$3:J5,"High Risk"),"") | M5: =RANK(H5,$H$3:$H$1002,0)+COUNTIF($H$3:H5,H5)-1 -> 516
A6: STU0004 | B6: Riya Sharma | C6: Female | D6: A | E6: 71.9 | F6: 4.9 | G6: 70 | H6: =ROUND(0.4*G6+0.3*E6+0.3*MIN(F6/10,1)*100,1) -> 64.3 | I6: =IF(H6>=50,"PASS","FAIL") -> PASS | J6: =IF(H6<50,"High Risk",IF(H6<65,"Medium Risk","Low Risk")) -> Medium Risk | L6: =IF(J6="High Risk",COUNTIF($J$3:J6,"High Risk"),"") | M6: =RANK(H6,$H$3:$H$1002,0)+COUNTIF($H$3:H6,H6)-1 -> 539
A7: STU0005 | B7: Anita Reddy | C7: Female | D7: D | E7: 62.8 | F7: 7.3 | G7: 61 | H7: =ROUND(0.4*G7+0.3*E7+0.3*MIN(F7/10,1)*100,1) -> 65.1 | I7: =IF(H7>=50,"PASS","FAIL") -> PASS | J7: =IF(H7<50,"High Risk",IF(H7<65,"Medium Risk","Low Risk")) -> Low Risk | L7: =IF(J7="High Risk",COUNTIF($J$3:J7,"High Risk"),"") | M7: =RANK(H7,$H$3:$H$1002,0)+COUNTIF($H$3:H7,H7)-1 -> 530
A8: STU0006 | B8: Bhavna Agarwal | C8: Female | D8: C | E8: 79.7 | F8: 8 | G8: 76 | H8: =ROUND(0.4*G8+0.3*E8+0.3*MIN(F8/10,1)*100,1) -> 78.3 | I8: =IF(H8>=50,"PASS","FAIL") -> PASS | J8: =IF(H8<50,"High Risk",IF(H8<65,"Medium Risk","Low Risk")) -> Low Risk | L8: =IF(J8="High Risk",COUNTIF($J$3:J8,"High Risk"),"") | M8: =RANK(H8,$H$3:$H$1002,0)+COUNTIF($H$3:H8,H8)-1 -> 273
A9: STU0007 | B9: Kunal Nair | C9: Male | D9: D | E9: 80.8 | F9: 7.6 | G9: 89 | H9: =ROUND(0.4*G9+0.3*E9+0.3*MIN(F9/10,1)*100,1) -> 82.6 | I9: =IF(H9>=50,"PASS","FAIL") -> PASS | J9: =IF(H9<50,"High Risk",IF(H9<65,"Medium Risk","Low Risk")) -> Low Risk | L9: =IF(J9="High Risk",COUNTIF($J$3:J9,"High Risk"),"") | M9: =RANK(H9,$H$3:$H$1002,0)+COUNTIF($H$3:H9,H9)-1 -> 205
A10: STU0008 | B10: Pooja Rao | C10: Female | D10: B | E10: 52.9 | F10: 3.8 | G10: 51 | H10: =ROUND(0.4*G10+0.3*E10+0.3*MIN(F10/10,1)*100,1) -> 47.7 | I10: =IF(H10>=50,"PASS","FAIL") -> FAIL | J10: =IF(H10<50,"High Risk",IF(H10<65,"Medium Risk","Low Risk")) -> High Risk | L10: =IF(J10="High Risk",COUNTIF($J$3:J10,"High Risk"),"") -> 1 | M10: =RANK(H10,$H$3:$H$1002,0)+COUNTIF($H$3:H10,H10)-1 -> 827
A11: STU0009 | B11: Ashok Desai | C11: Male | D11: A | E11: 64.9 | F11: 6.5 | G11: 49 | H11: =ROUND(0.4*G11+0.3*E11+0.3*MIN(F11/10,1)*100,1) -> 58.6 | I11: =IF(H11>=50,"PASS","FAIL") -> PASS | J11: =IF(H11<50,"High Risk",IF(H11<65,"Medium Risk","Low Risk")) -> Medium Risk | L11: =IF(J11="High Risk",COUNTIF($J$3:J11,"High Risk"),"") | M11: =RANK(H11,$H$3:$H$1002,0)+COUNTIF($H$3:H11,H11)-1 -> 651
A12: STU0010 | B12: Siddharth Iyer | C12: Male | D12: D | E12: 71.1 | F12: 7.8 | G12: 68 | H12: =ROUND(0.4*G12+0.3*E12+0.3*MIN(F12/10,1)*100,1) -> 71.9 | I12: =IF(H12>=50,"PASS","FAIL") -> PASS | J12: =IF(H12<50,"High Risk",IF(H12<65,"Medium Risk","Low Risk")) -> Low Risk | L12: =IF(J12="High Risk",COUNTIF($J$3:J12,"High Risk"),"") | M12: =RANK(H12,$H$3:$H$1002,0)+COUNTIF($H$3:H12,H12)-1 -> 386
A13: STU0011 | B13: Priya Gupta | C13: Female | D13: D | E13: 48 | F13: 2.9 | G13: 51 | H13: =ROUND(0.4*G13+0.3*E13+0.3*MIN(F13/10,1)*100,1) -> 43.5 | I13: =IF(H13>=50,"PASS","FAIL") -> FAIL | J13: =IF(H13<50,"High Risk",IF(H13<65,"Medium Risk","Low Risk")) -> High Risk | L13: =IF(J13="High Risk",COUNTIF($J$3:J13,"High Risk"),"") -> 2 | M13: =RANK(H13,$H$3:$H$1002,0)+COUNTIF($H$3:H13,H13)-1 -> 866
A14: STU0012 | B14: Anjali Reddy | C14: Female | D14: A | E14: 64.5 | F14: 5.9 | G14: 57 | H14: =ROUND(0.4*G14+0.3*E14+0.3*MIN(F14/10,1)*100,1) -> 59.9 | I14: =IF(H14>=50,"PASS","FAIL") -> PASS | J14: =IF(H14<50,"High Risk",IF(H14<65,"Medium Risk","Low Risk")) -> Medium Risk | L14: =IF(J14="High Risk",COUNTIF($J$3:J14,"High Risk"),"") | M14: =RANK(H14,$H$3:$H$1002,0)+COUNTIF($H$3:H14,H14)-1 -> 623
... A1002: STU1000 | B1002: Manisha Nair | C1002: Female | D1002: A | E1002: 73.9 | F1002: 8.4 | G1002: 77 | H1002: =ROUND(0.4*G1002+0.3*E1002+0.3*MIN(F1002/10,1)*100,1) -> 78.2 | I1002: =IF(H1002>=50,"PASS","FAIL") -> PASS | J1002: =IF(H1002<50,"High Risk",IF(H1002<65,"Medium Risk","Low Risk")) -> Low Risk | L1002: =IF(J1002="High Risk",COUNTIF($J$3:J1002,"High Risk"),"") | M1002: =RANK(H1002,$H$3:$H$1002,0)+COUNTIF($H$3:H1002,H1002)-1 -> 276

Sheet Pivot Summary
B2: Pivot-Style Summary — 15 Tables
B3: Formula-driven breakdowns that update automatically when Student Data changes. To build a live drag-and-drop native PivotTable instead: click any cell in the StudentDataTable on 'Student Data' -> Insert tab -> PivotTable.
B5: 1. By Risk Level
B6: Risk Level | C6: Students | D6: Avg Score | E6: Avg Attendance | F6: Avg Study Hrs | G6: Avg Prev Marks
B7: High Risk | C7: =COUNTIF('Student Data'!$J$3:$J$1002,B7) -> 197 | D7: =IFERROR(ROUND(AVERAGEIF('Student Data'!$J$3:$J$1002,B7,'Student Data'!$H$3:$H$1002),1),0) -> 38.5 | E7: =IFERROR(ROUND(AVERAGEIF('Student Data'!$J$3:$J$1002,B7,'Student Data'!$E$3:$E$1002),1),0) -> 52 | F7: =IFERROR(ROUND(AVERAGEIF('Student Data'!$J$3:$J$1002,B7,'Student Data'!$F$3:$F$1002),1),0) -> 2 | G7: =IFERROR(ROUND(AVERAGEIF('Student Data'!$J$3:$J$1002,B7,'Student Data'!$G$3:$G$1002),1),0) -> 42.5
B8: Medium Risk | C8: =COUNTIF('Student Data'!$J$3:$J$1002,B8) -> 272 | D8: =IFERROR(ROUND(AVERAGEIF('Student Data'!$J$3:$J$1002,B8,'Student Data'!$H$3:$H$1002),1),0) -> 57.5 | E8: =IFERROR(ROUND(AVERAGEIF('Student Data'!$J$3:$J$1002,B8,'Student Data'!$E$3:$E$1002),1),0) -> 68.4 | F8: =IFERROR(ROUND(AVERAGEIF('Student Data'!$J$3:$J$1002,B8,'Student Data'!$F$3:$F$1002),1),0) -> 4.6 | G8: =IFERROR(ROUND(AVERAGEIF('Student Data'!$J$3:$J$1002,B8,'Student Data'!$G$3:$G$1002),1),0) -> 58.3
B9: Low Risk | C9: =COUNTIF('Student Data'!$J$3:$J$1002,B9) -> 531 | D9: =IFERROR(ROUND(AVERAGEIF('Student Data'!$J$3:$J$1002,B9,'Student Data'!$H$3:$H$1002),1),0) -> 80 | E9: =IFERROR(ROUND(AVERAGEIF('Student Data'!$J$3:$J$1002,B9,'Student Data'!$E$3:$E$1002),1),0) -> 85.5 | F9: =IFERROR(ROUND(AVERAGEIF('Student Data'!$J$3:$J$1002,B9,'Student Data'!$F$3:$F$1002),1),0) -> 8.1 | G9: =IFERROR(ROUND(AVERAGEIF('Student Data'!$J$3:$J$1002,B9,'Student Data'!$G$3:$G$1002),1),0) -> 77
B11: 2. By Predicted Result
B12: Result | C12: Students | D12: Avg Score | E12: Avg Attendance | F12: Avg Study Hrs | G12: Avg Prev Marks
B13: PASS | C13: =COUNTIF('Student Data'!$I$3:$I$1002,B13) -> 803 | D13: =IFERROR(ROUND(AVERAGEIF('Student Data'!$I$3:$I$1002,B13,'Student Data'!$H$3:$H$1002),1),0) -> 72.4 | E13: =IFERROR(ROUND(AVERAGEIF('Student Data'!$I$3:$I$1002,B13,'Student Data'!$E$3:$E$1002),1),0) -> 79.7 | F13: =IFERROR(ROUND(AVERAGEIF('Student Data'!$I$3:$I$1002,B13,'Student Data'!$F$3:$F$1002),1),0) -> 6.9 | G13: =IFERROR(ROUND(AVERAGEIF('Student Data'!$I$3:$I$1002,B13,'Student Data'!$G$3:$G$1002),1),0) -> 70.6
B14: FAIL | C14: =COUNTIF('Student Data'!$I$3:$I$1002,B14) -> 197 | D14: =IFERROR(ROUND(AVERAGEIF('Student Data'!$I$3:$I$1002,B14,'Student Data'!$H$3:$H$1002),1),0) -> 38.5 | E14: =IFERROR(ROUND(AVERAGEIF('Student Data'!$I$3:$I$1002,B14,'Student Data'!$E$3:$E$1002),1),0) -> 52 | F14: =IFERROR(ROUND(AVERAGEIF('Student Data'!$I$3:$I$1002,B14,'Student Data'!$F$3:$F$1002),1),0) -> 2 | G14: =IFERROR(ROUND(AVERAGEIF('Student Data'!$I$3:$I$1002,B14,'Student Data'!$G$3:$G$1002),1),0) -> 42.5
B16: 3. By Performance Score Band
B17: Score Band | C17: Students | D17: % of Class
B18: 0-49 (Fail) | C18: =COUNTIFS('Student Data'!$H$3:$H$1002,">="&0,'Student Data'!$H$3:$H$1002,"<="&49.999) -> 197 | D18: =ROUND(C18/COUNTA('Student Data'!$A$3:$A$1002)*100,1)&"%" -> 19.7%
B19: 50-64 (Borderline) | C19: =COUNTIFS('Student Data'!$H$3:$H$1002,">="&50,'Student Data'!$H$3:$H$1002,"<="&64.999) -> 272 | D19: =ROUND(C19/COUNTA('Student Data'!$A$3:$A$1002)*100,1)&"%" -> 27.2%
B20: 65-79 (Good) | C20: =COUNTIFS('Student Data'!$H$3:$H$1002,">="&65,'Student Data'!$H$3:$H$1002,"<="&79.999) -> 283 | D20: =ROUND(C20/COUNTA('Student Data'!$A$3:$A$1002)*100,1)&"%" -> 28.3%
B21: 80-100 (Excellent) | C21: =COUNTIFS('Student Data'!$H$3:$H$1002,">="&80,'Student Data'!$H$3:$H$1002,"<="&100) -> 248 | D21: =ROUND(C21/COUNTA('Student Data'!$A$3:$A$1002)*100,1)&"%" -> 24.8%
B23: 4. By Attendance Band
B24: Attendance Band | C24: Students | D24: Avg Score | E24: Pass Rate
B25: <60% (Low) | C25: =COUNTIFS('Student Data'!$E$3:$E$1002,">="&0,'Student Data'!$E$3:$E$1002,"<="&59.999) -> 188 | D25: =IFERROR(ROUND(AVERAGEIFS('Student Data'!$H$3:$H$1002,'Student Data'!$E$3:$E$1002,">="&0,'Student Data'!$E$3:$E$1002,"<="&59.999),1),0) -> 41 | E25: =IFERROR(ROUND(COUNTIFS('Student Data'!$E$3:$E$1002,">="&0,'Student Data'!$E$3:$E$1002,"<="&59.999,'Student Data'!$I$3:$I$1002,"PASS")/C25*100,1)&"%",0) -> 22.9%
B26: 60-75% (Medium) | C26: =COUNTIFS('Student Data'!$E$3:$E$1002,">="&60,'Student Data'!$E$3:$E$1002,"<="&74.999) -> 314 | D26: =IFERROR(ROUND(AVERAGEIFS('Student Data'!$H$3:$H$1002,'Student Data'!$E$3:$E$1002,">="&60,'Student Data'!$E$3:$E$1002,"<="&74.999),1),0) -> 59.4 | E26: =IFERROR(ROUND(COUNTIFS('Student Data'!$E$3:$E$1002,">="&60,'Student Data'!$E$3:$E$1002,"<="&74.999,'Student Data'!$I$3:$I$1002,"PASS")/C26*100,1)&"%",0) -> 84.1%
B27: 75-90% (Good) | C27: =COUNTIFS('Student Data'!$E$3:$E$1002,">="&75,'Student Data'!$E$3:$E$1002,"<="&89.999) -> 305 | D27: =IFERROR(ROUND(AVERAGEIFS('Student Data'!$H$3:$H$1002,'Student Data'!$E$3:$E$1002,">="&75,'Student Data'!$E$3:$E$1002,"<="&89.999),1),0) -> 73.2 | E27: =IFERROR(ROUND(COUNTIFS('Student Data'!$E$3:$E$1002,">="&75,'Student Data'!$E$3:$E$1002,"<="&89.999,'Student Data'!$I$3:$I$1002,"PASS")/C27*100,1)&"%",0) -> 99.3%
B28: 90-100% (Excellent) | C28: =COUNTIFS('Student Data'!$E$3:$E$1002,">="&90,'Student Data'!$E$3:$E$1002,"<="&100) -> 193 | D28: =IFERROR(ROUND(AVERAGEIFS('Student Data'!$H$3:$H$1002,'Student Data'!$E$3:$E$1002,">="&90,'Student Data'!$E$3:$E$1002,"<="&100),1),0) -> 88.3 | E28: =IFERROR(ROUND(COUNTIFS('Student Data'!$E$3:$E$1002,">="&90,'Student Data'!$E$3:$E$1002,"<="&100,'Student Data'!$I$3:$I$1002,"PASS")/C28*100,1)&"%",0) -> 100%
B30: 5. By Study Hours/Week Band
B31: Study Hours Band | C31: Students | D31: Avg Score | E31: Pass Rate
B32: <3 hrs (Low) | C32: =COUNTIFS('Student Data'!$F$3:$F$1002,">="&0,'Student Data'!$F$3:$F$1002,"<="&2.999) -> 188 | D32: =IFERROR(ROUND(AVERAGEIFS('Student Data'!$H$3:$H$1002,'Student Data'!$F$3:$F$1002,">="&0,'Student Data'!$F$3:$F$1002,"<="&2.999),1),0) -> 40.1 | E32: =IFERROR(ROUND(COUNTIFS('Student Data'!$F$3:$F$1002,">="&0,'Student Data'!$F$3:$F$1002,"<="&2.999,'Student Data'!$I$3:$I$1002,"PASS")/C32*100,1)&"%",0) -> 20.7%
B33: 3-6 hrs (Moderate) | C33: =COUNTIFS('Student Data'!$F$3:$F$1002,">="&3,'Student Data'!$F$3:$F$1002,"<="&5.999) -> 312 | D33: =IFERROR(ROUND(AVERAGEIFS('Student Data'!$H$3:$H$1002,'Student Data'!$F$3:$F$1002,">="&3,'Student Data'!$F$3:$F$1002,"<="&5.999),1),0) -> 58.8 | E33: =IFERROR(ROUND(COUNTIFS('Student Data'!$F$3:$F$1002,">="&3,'Student Data'!$F$3:$F$1002,"<="&5.999,'Student Data'!$I$3:$I$1002,"PASS")/C33*100,1)&"%",0) -> 85.3%
B34: 6-9 hrs (Good) | C34: =COUNTIFS('Student Data'!$F$3:$F$1002,">="&6,'Student Data'!$F$3:$F$1002,"<="&8.999) -> 335 | D34: =IFERROR(ROUND(AVERAGEIFS('Student Data'!$H$3:$H$1002,'Student Data'!$F$3:$F$1002,">="&6,'Student Data'!$F$3:$F$1002,"<="&8.999),1),0) -> 74.3 | E34: =IFERROR(ROUND(COUNTIFS('Student Data'!$F$3:$F$1002,">="&6,'Student Data'!$F$3:$F$1002,"<="&8.999,'Student Data'!$I$3:$I$1002,"PASS")/C34*100,1)&"%",0) -> 99.4%
B35: 9+ hrs (High) | C35: =COUNTIFS('Student Data'!$F$3:$F$1002,">="&9,'Student Data'!$F$3:$F$1002,"<="&99) -> 165 | D35: =IFERROR(ROUND(AVERAGEIFS('Student Data'!$H$3:$H$1002,'Student Data'!$F$3:$F$1002,">="&9,'Student Data'!$F$3:$F$1002,"<="&99),1),0) -> 90.5 | E35: =IFERROR(ROUND(COUNTIFS('Student Data'!$F$3:$F$1002,">="&9,'Student Data'!$F$3:$F$1002,"<="&99,'Student Data'!$I$3:$I$1002,"PASS")/C35*100,1)&"%",0) -> 100%
B37: 6. By Previous Marks Band
B38: Previous Marks Band | C38: Students | D38: Avg Score | E38: Pass Rate
B39: 0-49 (Fail) | C39: =COUNTIFS('Student Data'!$G$3:$G$1002,">="&0,'Student Data'!$G$3:$G$1002,"<="&49.999) -> 177 | D39: =IFERROR(ROUND(AVERAGEIFS('Student Data'!$H$3:$H$1002,'Student Data'!$G$3:$G$1002,">="&0,'Student Data'!$G$3:$G$1002,"<="&49.999),1),0) -> 39.7 | E39: =IFERROR(ROUND(COUNTIFS('Student Data'!$G$3:$G$1002,">="&0,'Student Data'!$G$3:$G$1002,"<="&49.999,'Student Data'!$I$3:$I$1002,"PASS")/C39*100,1)&"%",0) -> 16.9%
B40: 50-64 (Borderline) | C40: =COUNTIFS('Student Data'!$G$3:$G$1002,">="&50,'Student Data'!$G$3:$G$1002,"<="&64.999) -> 316 | D40: =IFERROR(ROUND(AVERAGEIFS('Student Data'!$H$3:$H$1002,'Student Data'!$G$3:$G$1002,">="&50,'Student Data'!$G$3:$G$1002,"<="&64.999),1),0) -> 58.3 | E40: =IFERROR(ROUND(COUNTIFS('Student Data'!$G$3:$G$1002,">="&50,'Student Data'!$G$3:$G$1002,"<="&64.999,'Student Data'!$I$3:$I$1002,"PASS")/C40*100,1)&"%",0) -> 84.5%
B41: 65-79 (Good) | C41: =COUNTIFS('Student Data'!$G$3:$G$1002,">="&65,'Student Data'!$G$3:$G$1002,"<="&79.999) -> 295 | D41: =IFERROR(ROUND(AVERAGEIFS('Student Data'!$H$3:$H$1002,'Student Data'!$G$3:$G$1002,">="&65,'Student Data'!$G$3:$G$1002,"<="&79.999),1),0) -> 72.7 | E41: =IFERROR(ROUND(COUNTIFS('Student Data'!$G$3:$G$1002,">="&65,'Student Data'!$G$3:$G$1002,"<="&79.999,'Student Data'!$I$3:$I$1002,"PASS")/C41*100,1)&"%",0) -> 99.7%
B42: 80-100 (Excellent) | C42: =COUNTIFS('Student Data'!$G$3:$G$1002,">="&80,'Student Data'!$G$3:$G$1002,"<="&100) -> 212 | D42: =IFERROR(ROUND(AVERAGEIFS('Student Data'!$H$3:$H$1002,'Student Data'!$G$3:$G$1002,">="&80,'Student Data'!$G$3:$G$1002,"<="&100),1),0) -> 88.8 | E42: =IFERROR(ROUND(COUNTIFS('Student Data'!$G$3:$G$1002,">="&80,'Student Data'!$G$3:$G$1002,"<="&100,'Student Data'!$I$3:$I$1002,"PASS")/C42*100,1)&"%",0) -> 100%
B44: 7. By Gender
B45: Gender | C45: Students | D45: Avg Score | E45: Pass Rate | F45: High Risk Count
B46: Male | C46: =COUNTIF('Student Data'!$C$3:$C$1002,B46) -> 485 | D46: =IFERROR(ROUND(AVERAGEIF('Student Data'!$C$3:$C$1002,B46,'Student Data'!$H$3:$H$1002),1),0) -> 66.3 | E46: =IFERROR(ROUND(COUNTIFS('Student Data'!$C$3:$C$1002,B46,'Student Data'!$I$3:$I$1002,"PASS")/C46*100,1)&"%",0) -> 81.6% | F46: =COUNTIFS('Student Data'!$C$3:$C$1002,B46,'Student Data'!$J$3:$J$1002,"High Risk") -> 89
B47: Female | C47: =COUNTIF('Student Data'!$C$3:$C$1002,B47) -> 515 | D47: =IFERROR(ROUND(AVERAGEIF('Student Data'!$C$3:$C$1002,B47,'Student Data'!$H$3:$H$1002),1),0) -> 65.2 | E47: =IFERROR(ROUND(COUNTIFS('Student Data'!$C$3:$C$1002,B47,'Student Data'!$I$3:$I$1002,"PASS")/C47*100,1)&"%",0) -> 79% | F47: =COUNTIFS('Student Data'!$C$3:$C$1002,B47,'Student Data'!$J$3:$J$1002,"High Risk") -> 108
B49: 8. By Section
...

Sheet Dashboard
B2: Class Performance Dashboard
B3: All views in one sheet. Auto-updates from Student Data — 1,000 students.
B5: Total Students | D5: Predicted Pass | F5: Predicted Fail | H5: Class Avg Score | J5: Overall Pass Rate
B6: =COUNTA('Student Data'!$A$3:$A$1002) -> 1000 | D6: =COUNTIF('Student Data'!$I$3:$I$1002,"PASS") -> 803 | F6: =COUNTIF('Student Data'!$I$3:$I$1002,"FAIL") -> 197 | H6: =ROUND(AVERAGE('Student Data'!$H$3:$H$1002),1) -> 65.7 | J6: =ROUND(COUNTIF('Student Data'!$I$3:$I$1002,"PASS")/COUNTA('Student Data'!$A$3:$A$1002)*100,1)&"%" -> 80.3%
B8: High Risk | D8: Medium Risk | F8: Low Risk | H8: Attendance Correlation | J8: Study Hrs Correlation
B9: =COUNTIF('Student Data'!$J$3:$J$1002,"High Risk") -> 197 | D9: =COUNTIF('Student Data'!$J$3:$J$1002,"Medium Risk") -> 272 | F9: =COUNTIF('Student Data'!$J$3:$J$1002,"Low Risk") -> 531 | H9: =Insights!C6 -> Correlation | J9: =Insights!C7 -> 0.89
B11: 1. Risk & Result Overview
B29: 2. Risk Analysis — Avg Score by Risk Level
B47: 3. Attendance Analysis
B65: 4. Study Hours Analysis
B83: 5. Previous Marks Analysis
B101: 6. Performance Score Distribution
B119: 7. Gender-Wise Performance
B137: 8. Section-Wise Performance
B155: 9. Students Needing Immediate Support (High Risk, top 30 by row order)
B156: Student ID | C156: Name | D156: Performance Score | E156: Predicted Result
B157: =IFERROR(INDEX('Student Data'!$A$3:$A$1002,MATCH(1,'Student Data'!$L$3:$L$1002,0)),"") -> STU0008 | C157: =IFERROR(INDEX('Student Data'!$B$3:$B$1002,MATCH(1,'Student Data'!$L$3:$L$1002,0)),"") -> Pooja Rao | D157: =IFERROR(INDEX('Student Data'!$H$3:$H$1002,MATCH(1,'Student Data'!$L$3:$L$1002,0)),"") -> 47.7 | E157: =IFERROR(INDEX('Student Data'!$I$3:$I$1002,MATCH(1,'Student Data'!$L$3:$L$1002,0)),"") -> FAIL
B158: =IFERROR(INDEX('Student Data'!$A$3:$A$1002,MATCH(2,'Student Data'!$L$3:$L$1002,0)),"") -> STU0011 | C158: =IFERROR(INDEX('Student Data'!$B$3:$B$1002,MATCH(2,'Student Data'!$L$3:$L$1002,0)),"") -> Priya Gupta | D158: =IFERROR(INDEX('Student Data'!$H$3:$H$1002,MATCH(2,'Student Data'!$L$3:$L$1002,0)),"") -> 43.5 | E158: =IFERROR(INDEX('Student Data'!$I$3:$I$1002,MATCH(2,'Student Data'!$L$3:$L$1002,0)),"") -> FAIL
B159: =IFERROR(INDEX('Student Data'!$A$3:$A$1002,MATCH(3,'Student Data'!$L$3:$L$1002,0)),"") -> STU0016 | C159: =IFERROR(INDEX('Student Data'!$B$3:$B$1002,MATCH(3,'Student Data'!$L$3:$L$1002,0)),"") -> Sneha Nair | D159: =IFERROR(INDEX('Student Data'!$H$3:$H$1002,MATCH(3,'Student Data'!$L$3:$L$1002,0)),"") -> 27.2 | E159: =IFERROR(INDEX('Student Data'!$I$3:$I$1002,MATCH(3,'Student Data'!$L$3:$L$1002,0)),"") -> FAIL
B160: =IFERROR(INDEX('Student Data'!$A$3:$A$1002,MATCH(4,'Student Data'!$L$3:$L$1002,0)),"") -> STU0017 | C160: =IFERROR(INDEX('Student Data'!$B$3:$B$1002,MATCH(4,'Student Data'!$L$3:$L$1002,0)),"") -> Sanjay Shah | D160: =IFERROR(INDEX('Student Data'!$H$3:$H$1002,MATCH(4,'Student Data'!$L$3:$L$1002,0)),"") -> 34.9 | E160: =IFERROR(INDEX('Student Data'!$I$3:$I$1002,MATCH(4,'Student Data'!$L$3:$L$1002,0)),"") -> FAIL
B161: =IFERROR(INDEX('Student Data'!$A$3:$A$1002,MATCH(5,'Student Data'!$L$3:$L$1002,0)),"") -> STU0026 | C161: =IFERROR(INDEX('Student Data'!$B$3:$B$1002,MATCH(5,'Student Data'!$L$3:$L$1002,0)),"") -> Neha Sinha | D161: =IFERROR(INDEX('Student Data'!$H$3:$H$1002,MATCH(5,'Student Data'!$L$3:$L$1002,0)),"") -> 42.9 | E161: =IFERROR(INDEX('Student Data'!$I$3:$I$1002,MATCH(5,'Student Data'!$L$3:$L$1002,0)),"") -> FAIL
B162: =IFERROR(INDEX('Student Data'!$A$3:$A$1002,MATCH(6,'Student Data'!$L$3:$L$1002,0)),"") -> STU0035 | C162: =IFERROR(INDEX('Student Data'!$B$3:$B$1002,MATCH(6,'Student Data'!$L$3:$L$1002,0)),"") -> Aditya Dutta | D162: =IFERROR(INDEX('Student Data'!$H$3:$H$1002,MATCH(6,'Student Data'!$L$3:$L$1002,0)),"") -> 48.6 | E162: =IFERROR(INDEX('Student Data'!$I$3:$I$1002,MATCH(6,'Student Data'!$L$3:$L$1002,0)),"") -> FAIL
B163: =IFERROR(INDEX('Student Data'!$A$3:$A$1002,MATCH(7,'Student Data'!$L$3:$L$1002,0)),"") -> STU0047 | C163: =IFERROR(INDEX('Student Data'!$B$3:$B$1002,MATCH(7,'Student Data'!$L$3:$L$1002,0)),"") -> Lakshmi Verma | D163: =IFERROR(INDEX('Student Data'!$H$3:$H$1002,MATCH(7,'Student Data'!$L$3:$L$1002,0)),"") -> 49.1 | E163: =IFERROR(INDEX('Student Data'!$I$3:$I$1002,MATCH(7,'Student Data'!$L$3:$L$1002,0)),"") -> FAIL
B164: =IFERROR(INDEX('Student Data'!$A$3:$A$1002,MATCH(8,'Student Data'!$L$3:$L$1002,0)),"") -> STU0052 | C164: =IFERROR(INDEX('Student Data'!$B$3:$B$1002,MATCH(8,'Student Data'!$L$3:$L$1002,0)),"") -> Isha Desai | D164: =IFERROR(INDEX('Student Data'!$H$3:$H$1002,MATCH(8,'Student Data'!$L$3:$L$1002,0)),"") -> 33.9 | E164: =IFERROR(INDEX('Student Data'!$I$3:$I$1002,MATCH(8,'Student Data'!$L$3:$L$1002,0)),"") -> FAIL
B165: =IFERROR(INDEX('Student Data'!$A$3:$A$1002,MATCH(9,'Student Data'!$L$3:$L$1002,0)),"") -> STU0057 | C165: =IFERROR(INDEX('Student Data'!$B$3:$B$1002,MATCH(9,'Student Data'!$L$3:$L$1002,0)),"") -> Neha Singh | D165: =IFERROR(INDEX('Student Data'!$H$3:$H$1002,MATCH(9,'Student Data'!$L$3:$L$1002,0)),"") -> 46.4 | E165: =IFERROR(INDEX('Student Data'!$I$3:$I$1002,MATCH(9,'Student Data'!$L$3:$L$1002,0)),"") -> FAIL
B166: =IFERROR(INDEX('Student Data'!$A$3:$A$1002,MATCH(10,'Student Data'!$L$3:$L$1002,0)),"") -> STU0063 | C166: =IFERROR(INDEX('Student Data'!$B$3:$B$1002,MATCH(10,'Student Data'!$L$3:$L$1002,0)),"") -> Rahul Sharma | D166: =IFERROR(INDEX('Student Data'!$H$3:$H$1002,MATCH(10,'Student Data'!$L$3:$L$1002,0)),"") -> 22.9 | E166: =IFERROR(INDEX('Student Data'!$I$3:$I$1002,MATCH(10,'Student Data'!$L$3:$L$1002,0)),"") -> FAIL
B167: =IFERROR(INDEX('Student Data'!$A$3:$A$1002,MATCH(11,'Student Data'!$L$3:$L$1002,0)),"") -> STU0064 | C167: =IFERROR(INDEX('Student Data'!$B$3:$B$1002,MATCH(11,'Student Data'!$L$3:$L$1002,0)),"") -> Anita Menon | D167: =IFERROR(INDEX('Student Data'!$H$3:$H$1002,MATCH(11,'Student Data'!$L$3:$L$1002,0)),"") -> 26.7 | E167: =IFERROR(INDEX('Student Data'!$I$3:$I$1002,MATCH(11,'Student Data'!$L$3:$L$1002,0)),"") -> FAIL
B168: =IFERROR(INDEX('Student Data'!$A$3:$A$1002,MATCH(12,'Student Data'!$L$3:$L$1002,0)),"") -> STU0068 | C168: =IFERROR(INDEX('Student Data'!$B$3:$B$1002,MATCH(12,'Student Data'!$L$3:$L$1002,0)),"") -> Swati Pandey | D168: =IFERROR(INDEX('Student Data'!$H$3:$H$1002,MATCH(12,'Student Data'!$L$3:$L$1002,0)),"") -> 28.8 | E168: =IFERROR(INDEX('Student Data'!$I$3:$I$1002,MATCH(12,'Student Data'!$L$3:$L$1002,0)),"") -> FAIL
B169: =IFERROR(INDEX('Student Data'!$A$3:$A$1002,MATCH(13,'Student Data'!$L$3:$L$1002,0)),"") -> STU0070 | C169: =IFERROR(INDEX('Student Data'!$B$3:$B$1002,MATCH(13,'Student Data'!$L$3:$L$1002,0)),"") -> Gaurav Mehta | D169: =IFERROR(INDEX('Student Data'!$H$3:$H$1002,MATCH(13,'Student Data'!$L$3:$L$1002,0)),"") -> 39.9 | E169: =IFERROR(INDEX('Student Data'!$I$3:$I$1002,MATCH(13,'Student Data'!$L$3:$L$1002,0)),"") -> FAIL
B170: =IFERROR(INDEX('Student Data'!$A$3:$A$1002,MATCH(14,'Student Data'!$L$3:$L$1002,0)),"") -> STU0073 | C170: =IFERROR(INDEX('Student Data'!$B$3:$B$1002,MATCH(14,'Student Data'!$L$3:$L$1002,0)),"") -> Meera Iyer | D170: =IFERROR(INDEX('Student Data'!$H$3:$H$1002,MATCH(14,'Student Data'!$L$3:$L$1002,0)),"") -> 47.4 | E170: =IFERROR(INDEX('Student Data'!$I$3:$I$1002,MATCH(14,'Student Data'!$L$3:$L$1002,0)),"") -> FAIL
B171: =IFERROR(INDEX('Student Data'!$A$3:$A$1002,MATCH(15,'Student Data'!$L$3:$L$1002,0)),"") -> STU0078 | C171: =IFERROR(INDEX('Student Data'!$B$3:$B$1002,MATCH(15,'Student Data'!$L$3:$L$1002,0)),"") -> Aarti Chauhan | D171: =IFERROR(INDEX('Student Data'!$H$3:$H$1002,MATCH(15,'Student Data'!$L$3:$L$1002,0)),"") -> 40.3 | E171: =IFERROR(INDEX('Student Data'!$I$3:$I$1002,MATCH(15,'Student Data'!$L$3:$L$1002,0)),"") -> FAIL
B172: =IFERROR(INDEX('Student Data'!$A$3:$A$1002,MATCH(16,'Student Data'!$L$3:$L$1002,0)),"") -> STU0086 | C172: =IFERROR(INDEX('Student Data'!$B$3:$B$1002,MATCH(16,'Student Data'!$L$3:$L$1002,0)),"") -> Shreya Malhotra | D172: =IFERROR(INDEX('Student Data'!$H$3:$H$1002,MATCH(16,'Student Data'!$L$3:$L$1002,0)),"") -> 44.6 | E172: =IFERROR(INDEX('Student Data'!$I$3:$I$1002,MATCH(16,'Student Data'!$L$3:$L$1002,0)),"") -> FAIL
B173: =IFERROR(INDEX('Student Data'!$A$3:$A$1002,MATCH(17,'Student Data'!$L$3:$L$1002,0)),"") -> STU0095 | C173: =IFERROR(INDEX('Student Data'!$B$3:$B$1002,MATCH(17,'Student Data'!$L$3:$L$1002,0)),"") -> Manoj Sinha | D173: =IFERROR(INDEX('Student Data'!$H$3:$H$1002,MATCH(17,'Student Data'!$L$3:$L$1002,0)),"") -> 36.9 | E173: =IFERROR(INDEX('Student Data'!$I$3:$I$1002,MATCH(17,'Student Data'!$L$3:$L$1002,0)),"") -> FAIL
B174: =IFERROR(INDEX('Student Data'!$A$3:$A$1002,MATCH(18,'Student Data'!$L$3:$L$1002,0)),"") -> STU0100 | C174: =IFERROR(INDEX('Student Data'!$B$3:$B$1002,MATCH(18,'Student Data'!$L$3:$L$1002,0)),"") -> Nikhil Sinha | D174: =IFERROR(INDEX('Student Data'!$H$3:$H$1002,MATCH(18,'Student Data'!$L$3:$L$1002,0)),"") -> 38.6 | E174: =IFERROR(INDEX('Student Data'!$I$3:$I$1002,MATCH(18,'Student Data'!$L$3:$L$1002,0)),"") -> FAIL
B175: =IFERROR(INDEX('Student Data'!$A$3:$A$1002,MATCH(19,'Student Data'!$L$3:$L$1002,0)),"") -> STU0102 | C175: =IFERROR(INDEX('Student Data'!$B$3:$B$1002,MATCH(19,'Student Data'!$L$3:$L$1002,0)),"") -> Payal Kumar | D175: =IFERROR(INDEX('Student Data'!$H$3:$H$1002,MATCH(19,'Student Data'!$L$3:$L$1002,0)),"") -> 47 | E175: =IFERROR(INDEX('Student Data'!$I$3:$I$1002,MATCH(19,'Student Data'!$L$3:$L$1002,0)),"") -> FAIL
B176: =IFERROR(INDEX('Student Data'!$A$3:$A$1002,MATCH(20,'Student Data'!$L$3:$L$1002,0)),"") -> STU0104 | C176: =IFERROR(INDEX('Student Data'!$B$3:$B$1002,MATCH(20,'Student Data'!$L$3:$L$1002,0)),"") -> Kunal Bansal | D176: =IFERROR(INDEX('Student Data'!$H$3:$H$1002,MATCH(20,'Student Data'!$L$3:$L$1002,0)),"") -> 43.5 | E176: =IFERROR(INDEX('Student Data'!$I$3:$I$1002,MATCH(20,'Student Data'!$L$3:$L$1002,0)),"") -> FAIL
B177: =IFERROR(INDEX('Student Data'!$A$3:$A$1002,MATCH(21,'Student Data'!$L$3:$L$1002,0)),"") -> STU0105 | C177: =IFERROR(INDEX('Student Data'!$B$3:$B$1002,MATCH(21,'Student Data'!$L$3:$L$1002,0)),"") -> Suman Reddy | D177: =IFERROR(INDEX('Student Data'!$H$3:$H$1002,MATCH(21,'Student Data'!$L$3:$L$1002,0)),"") -> 40.7 | E177: =IFERROR(INDEX('Student Data'!$I$3:$I$1002,MATCH(21,'Student Data'!$L$3:$L$1002,0)),"") -> FAIL
B178: =IFERROR(INDEX('Student Data'!$A$3:$A$1002,MATCH(22,'Student Data'!$L$3:$L$1002,0)),"") -> STU0115 | C178: =IFERROR(INDEX('Student Data'!$B$3:$B$1002,MATCH(22,'Student Data'!$L$3:$L$1002,0)),"") -> Ankit Desai | D178: =IFERROR(INDEX('Student Data'!$H$3:$H$1002,MATCH(22,'Student Data'!$L$3:$L$1002,0)),"") -> 17 | E178: =IFERROR(INDEX('Student Data'!$I$3:$I$1002,MATCH(22,'Student Data'!$L$3:$L$1002,0)),"") -> FAIL
B179: =IFERROR(INDEX('Student Data'!$A$3:$A$1002,MATCH(23,'Student Data'!$L$3:$L$1002,0)),"") -> STU0116 | C179: =IFERROR(INDEX('Student Data'!$B$3:$B$1002,MATCH(23,'Student Data'!$L$3:$L$1002,0)),"") -> Isha Iyer | D179: =IFERROR(INDEX('Student Data'!$H$3:$H$1002,MATCH(23,'Student Data'!$L$3:$L$1002,0)),"") -> 46.6 | E179: =IFERROR(INDEX('Student Data'!$I$3:$I$1002,MATCH(23,'Student Data'!$L$3:$L$1002,0)),"") -> FAIL
B180: =IFERROR(INDEX('Student Data'!$A$3:$A$1002,MATCH(24,'Student Data'!$L$3:$L$1002,0)),"") -> STU0119 | C180: =IFERROR(INDEX('Student Data'!$B$3:$B$1002,MATCH(24,'Student Data'!$L$3:$L$1002,0)),"") -> Ritu Sinha | D180: =IFERROR(INDEX('Student Data'!$H$3:$H$1002,MATCH(24,'Student Data'!$L$3:$L$1002,0)),"") -> 40.1 | E180: =IFERROR(INDEX('Student Data'!$I$3:$I$1002,MATCH(24,'Student Data'!$L$3:$L$1002,0)),"") -> FAIL
...

Sheet Insights
B2: Key Insights & Correlations
B3: Auto-calculated from Student Data. Correlation ranges from -1 to +1: closer to +1 means the factor rises together with the performance score.
B5: Correlation with Performance Score | F5: A | G5: =IFERROR(ROUND(AVERAGEIF('Student Data'!$D$3:$D$1002,F5,'Student Data'!$H$3:$H$1002),1),0) -> 66.8
B6: Factor | C6: Correlation | D6: What it means | F6: B | G6: =IFERROR(ROUND(AVERAGEIF('Student Data'!$D$3:$D$1002,F6,'Student Data'!$H$3:$H$1002),1),0) -> 64.9
B7: Attendance (%) | C7: =ROUND(CORREL('Student Data'!$E$3:$E$1002,'Student Data'!$H$3:$H$1002),2) -> 0.89 | D7: How strongly attendance tracks with the predicted performance score. | F7: C | G7: =IFERROR(ROUND(AVERAGEIF('Student Data'!$D$3:$D$1002,F7,'Student Data'!$H$3:$H$1002),1),0) -> 66.3
B8: Study Hours/Week | C8: =ROUND(CORREL('Student Data'!$F$3:$F$1002,'Student Data'!$H$3:$H$1002),2) -> 0.91 | D8: How strongly weekly study time tracks with the predicted score. | F8: D | G8: =IFERROR(ROUND(AVERAGEIF('Student Data'!$D$3:$D$1002,F8,'Student Data'!$H$3:$H$1002),1),0) -> 64.5
B9: Previous Marks (%) | C9: =ROUND(CORREL('Student Data'!$G$3:$G$1002,'Student Data'!$H$3:$H$1002),2) -> 0.92 | D9: How strongly past academic marks track with the predicted score.
B11: Class-Wide KPIs
B12: Metric | C12: Value | D12: What it means
B13: Overall Pass Rate | C13: =ROUND(COUNTIF('Student Data'!$I$3:$I$1002,"PASS")/COUNTA('Student Data'!$A$3:$A$1002)*100,1)&"%" -> 80.3% | D13: Share of the 1,000 students predicted to pass under the current scoring model.
B14: High Risk Share | C14: =ROUND(COUNTIF('Student Data'!$J$3:$J$1002,"High Risk")/COUNTA('Student Data'!$A$3:$A$1002)*100,1)&"%" -> 19.7% | D14: Share of students flagged High Risk (score below 50) — the group needing immediate support.
B15: Avg Attendance (Fail group) | C15: =ROUND(AVERAGEIF('Student Data'!$I$3:$I$1002,"FAIL",'Student Data'!$E$3:$E$1002),1) -> 52 | D15: Average attendance among students predicted to fail — compare to the pass group below.
B16: Avg Attendance (Pass group) | C16: =ROUND(AVERAGEIF('Student Data'!$I$3:$I$1002,"PASS",'Student Data'!$E$3:$E$1002),1) -> 79.7 | D16: Average attendance among students predicted to pass.
B17: Top Section by Avg Score | C17: =INDEX($F$5:$F$8,MATCH(MAX($G$5:$G$8),$G$5:$G$8,0)) -> A | D17: The class section with the highest average performance score.
B19: How To Read & Act On These Insights
B20: 1. Start with the correlation table above — whichever factor has the highest correlation with Performance Score is the biggest lever for improving outcomes class-wide.
B21: 2. Use the 'By Risk Level' pivot table (Pivot Summary sheet) to see how many students are High/Medium/Low Risk, and the averages that define each group.
B22: 3. Open Dashboard 2 (Risk Analysis) and Dashboard 9 (Top & Bottom Performers) to get a short list of names to act on this week — the High Risk list and the Bottom 10 table.
B23: 4. Cross-check Dashboards 3-6 (Attendance, Study Hours, Previous Marks, Score Bands) to decide whether an intervention should focus on attendance drives, study-skills coaching, or catch-up classes for weak prior performance.
B24: 5. Re-run this analysis every few weeks: paste new Attendance / Study Hours / Previous Marks into 'Student Data' and every formula, pivot table, and dashboard recalculates automatically.
